Workbook

Sheet Transcription
A1: SR# | B1: =IFERROR(__xludf.DUMMYFUNCTION("IMPORTRANGE(""https://docs.google.com/spreadsheets/d/1y4c8qrWl_VAhJwJxhjPm9yFj2gC10Yzsv1SnCBUOPpQ/edit?gid=68623660#gid=68623660"",""Form responses 1!A1:AM1000"")"),"Timestamp") -> Timestamp | C1: =IFERROR(__xludf.DUMMYFUNCTION("""COMPUTED_VALUE"""),"آپ کا نام کیا ہے؟") -> آپ کا نام کیا ہے؟ | D1: =IFERROR(__xludf.DUMMYFUNCTION("""COMPUTED_VALUE"""),"آپ کا فون نمبر کیا ہے؟") -> آپ کا فون نمبر کیا ہے؟ | E1: =IFERROR(__xludf.DUMMYFUNCTION("""COMPUTED_VALUE"""),"مسجد کا نام لکھیں") -> مسجد کا نام لکھیں | F1: =IFERROR(__xludf.DUMMYFUNCTION("""COMPUTED_VALUE"""),"مسجد کی آئی ڈی نمبر کیا ہے جس کے لیے آپ نے خطبہ لکھا ہے۔") -> مسجد کی آئی ڈی نمبر کیا ہے جس کے لیے آپ نے خطبہ لکھا ہے۔ | G1: =IFERROR(__xludf.DUMMYFUNCTION("""COMPUTED_VALUE"""),"اب ہم آپ سے امام کے بیان کے بارے میں کچھ سوال پوچھیں گے- ان سوالوں کا جواب صرف تب دیں جب آپ بیان کو پوری طرح سے لکھ لیں- کیا ہم نے آپ کو امام کے بیان سے موازنہ کرنے کے لیے کوئی رسم الخط دیا ہے؟ اگر ہم نے آپ کو پڑوسیوں یا عورتوں کے حقوق کے اوپر کوئی رسم ا"&"لخط نہیں دیا تو یہاں نہیں لکھیں-") -> اب ہم آپ سے امام کے بیان کے بارے میں کچھ سوال پوچھیں گے- ان سوالوں کا جواب صرف تب دیں جب آپ بیان کو پوری طرح سے لکھ لیں- کیا ہم نے آپ کو امام کے بیان سے موازنہ کرنے کے لیے کوئی رسم الخط دیا ہے؟ اگر ہم نے آپ کو پڑوسیوں یا عورتوں کے حقوق کے اوپر کوئی رسم الخط نہیں دیا تو یہاں نہیں لکھیں- | H1: =IFERROR(__xludf.DUMMYFUNCTION("""COMPUTED_VALUE"""),"٠ سے ١٠ کے پیمانے پر، امام نے رسم الخط کی کتنی قریب سے پیروی کی؟") -> ٠ سے ١٠ کے پیمانے پر، امام نے رسم الخط کی کتنی قریب سے پیروی کی؟ | I1: =IFERROR(__xludf.DUMMYFUNCTION("""COMPUTED_VALUE"""),"٠ سے ١٠ کے پیمانے پر، امام نے دیے ہوۓ رسم الخط میں اپنی طرف سے کتنا اضافی مواد شامل کیا؟") -> ٠ سے ١٠ کے پیمانے پر، امام نے دیے ہوۓ رسم الخط میں اپنی طرف سے کتنا اضافی مواد شامل کیا؟ | J1: =IFERROR(__xludf.DUMMYFUNCTION("""COMPUTED_VALUE"""),"٠ سے ١٠ کے پیمانے پر، امام کے بیان کا مجموعی پیغام دیے ہوۓ رسم الخط کے پیغام سے کتنا ملتا جلتا تھا؟") -> ٠ سے ١٠ کے پیمانے پر، امام کے بیان کا مجموعی پیغام دیے ہوۓ رسم الخط کے پیغام سے کتنا ملتا جلتا تھا؟ | K1: =IFERROR(__xludf.DUMMYFUNCTION("""COMPUTED_VALUE"""),"٠ سے ١٠ کے پیمانے پر جہاں 0 کا مطلب ہے بالکل نہیں، 5 کا مطلب ہے کچھ حد تک، اور 10 کا مطلب ہے بہت زیادہ، امام نے اپنے بیان میں عورتوں کے حقوق پر کتنی گفتگو کی؟ اگر امام نے کسی اور موضوع پر بات کی (جیسے کہ پڑوسیوں کے حقوق) اور عورتوں کے حقوق پر بالکل بات ن"&"ہیں کی تو یہاں 0 لکھیں-") -> ٠ سے ١٠ کے پیمانے پر جہاں 0 کا مطلب ہے بالکل نہیں، 5 کا مطلب ہے کچھ حد تک، اور 10 کا مطلب ہے بہت زیادہ، امام نے اپنے بیان میں عورتوں کے حقوق پر کتنی گفتگو کی؟ اگر امام نے کسی اور موضوع پر بات کی (جیسے کہ پڑوسیوں کے حقوق) اور عورتوں کے حقوق پر بالکل بات نہیں کی تو یہاں 0 لکھیں- | L1: =IFERROR(__xludf.DUMMYFUNCTION("""COMPUTED_VALUE"""),"٠ سے ١٠ کے پیمانے پر، امام نے اپنے بیان میں پڑوسیوں کے حقوق پر کتنی گفتگو کی؟ اگر امام نے کسی اور موضوع پر بات کی (جیسے کہ عورتوں کے حقوق) اور پڑوسیوں کے حقوق پر بالکل بات نہیں کی تو یہاں 0 لکھیں-") -> ٠ سے ١٠ کے پیمانے پر، امام نے اپنے بیان میں پڑوسیوں کے حقوق پر کتنی گفتگو کی؟ اگر امام نے کسی اور موضوع پر بات کی (جیسے کہ عورتوں کے حقوق) اور پڑوسیوں کے حقوق پر بالکل بات نہیں کی تو یہاں 0 لکھیں- | M1: =IFERROR(__xludf.DUMMYFUNCTION("""COMPUTED_VALUE"""),"٠ سے ١٠ کے پیمانے پر، امام نے اپنے بیان میں کس حد تک نمازیوں کو عورتوں کے ساتھ اچھا سلوک کرنے کو کہا؟ اگر امام نے کسی اور موضوع پر بات کی (جیسے کہ پڑوسیوں پر) اور عورتوں پر بالکل بات نہیں کی تو یہاں 0 لکھیں-") -> ٠ سے ١٠ کے پیمانے پر، امام نے اپنے بیان میں کس حد تک نمازیوں کو عورتوں کے ساتھ اچھا سلوک کرنے کو کہا؟ اگر امام نے کسی اور موضوع پر بات کی (جیسے کہ پڑوسیوں پر) اور عورتوں پر بالکل بات نہیں کی تو یہاں 0 لکھیں- | N1: =IFERROR(__xludf.DUMMYFUNCTION("""COMPUTED_VALUE"""),"٠ سے ١٠ کے پیمانے پر، امام نے اپنے بیان میں کس حد تک نمازیوں کو پڑوسیوں کے ساتھ اچھا سلوک کرنے کو کہا؟ اگر امام نے کسی اور موضوع پر بات کی (جیسے کہ عورتوں پر) اور پڑوسیوں پر بالکل بات نہیں کی تو یہاں 0 لکھیں-") -> ٠ سے ١٠ کے پیمانے پر، امام نے اپنے بیان میں کس حد تک نمازیوں کو پڑوسیوں کے ساتھ اچھا سلوک کرنے کو کہا؟ اگر امام نے کسی اور موضوع پر بات کی (جیسے کہ عورتوں پر) اور پڑوسیوں پر بالکل بات نہیں کی تو یہاں 0 لکھیں- | O1: =IFERROR(__xludf.DUMMYFUNCTION("""COMPUTED_VALUE"""),"٠ سے ١٠ کے پیمانے پر، امام نے اپنے بیان میں خواتین کی تعلیم اور ملازمت کی کس حد تک حوصلہ افزائی کی؟ اگر امام نے کسی اور موضوع پر بات کی اور عورتوں کی تعلیم یا ملازمت پر بالکل بات نہیں کی تو یہاں 0 لکھیں-") -> ٠ سے ١٠ کے پیمانے پر، امام نے اپنے بیان میں خواتین کی تعلیم اور ملازمت کی کس حد تک حوصلہ افزائی کی؟ اگر امام نے کسی اور موضوع پر بات کی اور عورتوں کی تعلیم یا ملازمت پر بالکل بات نہیں کی تو یہاں 0 لکھیں- | P1: =IFERROR(__xludf.DUMMYFUNCTION("""COMPUTED_VALUE"""),"٠ سے ١٠ کے پیمانے پر، امام نے اپنے بیان میں کس حد تک نمازیوں کو محلے کو صاف رکھنے اور پڑوسیوں کی مدد کرنے کو کہا؟ اگر امام نے کسی اور موضوع پر بات کی اور پڑوسیوں یا محلے پر بالکل بات نہیں کی تو یہاں 0 لکھیں-") -> ٠ سے ١٠ کے پیمانے پر، امام نے اپنے بیان میں کس حد تک نمازیوں کو محلے کو صاف رکھنے اور پڑوسیوں کی مدد کرنے کو کہا؟ اگر امام نے کسی اور موضوع پر بات کی اور پڑوسیوں یا محلے پر بالکل بات نہیں کی تو یہاں 0 لکھیں- | Q1: =IFERROR(__xludf.DUMMYFUNCTION("""COMPUTED_VALUE"""),"کیا امام نے نمازیوں سے اگلے ہفتے اپنی بیویوں کے ساتھ اپنی بیٹیوں کی تعلیم یا نوکری کے بارے میں بات کرنے کو کہا؟ اگر امام نے کسی اور موضوع پر بات کی یا عورتوں پر بات کی مگر نمازیوں کو بیویوں کےساتھ بیٹیوں کی تعلیم یا نوکری کے بارے میں بات کرنے کو نہیں کہا"&"، تو یہاں نہیں لکھیں-") -> کیا امام نے نمازیوں سے اگلے ہفتے اپنی بیویوں کے ساتھ اپنی بیٹیوں کی تعلیم یا نوکری کے بارے میں بات کرنے کو کہا؟ اگر امام نے کسی اور موضوع پر بات کی یا عورتوں پر بات کی مگر نمازیوں کو بیویوں کےساتھ بیٹیوں کی تعلیم یا نوکری کے بارے میں بات کرنے کو نہیں کہا، تو یہاں نہیں لکھیں- | R1: =IFERROR(__xludf.DUMMYFUNCTION("""COMPUTED_VALUE"""),"کیا امام نے نمازیوں کو اگلے ہفتے اپنے محلے کو صاف کرنے کے لئے کچھ وقت نکالنے کو کہا؟ اگر امام نے کسی اور موضوع پر بات کی یا پڑوس کی صفائی پر بات کی مگر نمازیوں کو پڑوس کی صفائی کے لئے وقت نکالنے کو نہیں کہا، تو یہاں نہیں لکھیں-") -> کیا امام نے نمازیوں کو اگلے ہفتے اپنے محلے کو صاف کرنے کے لئے کچھ وقت نکالنے کو کہا؟ اگر امام نے کسی اور موضوع پر بات کی یا پڑوس کی صفائی پر بات کی مگر نمازیوں کو پڑوس کی صفائی کے لئے وقت نکالنے کو نہیں کہا، تو یہاں نہیں لکھیں- | S1: =IFERROR(__xludf.DUMMYFUNCTION("""COMPUTED_VALUE"""),"کیا امام نے نمازیوں سے کہا کہ جو کچھ انہوں نے جمعہ کے بیان میں سنا ہے وہ اپنی بیویوں کو بھی بتائیں؟") -> کیا امام نے نمازیوں سے کہا کہ جو کچھ انہوں نے جمعہ کے بیان میں سنا ہے وہ اپنی بیویوں کو بھی بتائیں؟ | T1: =IFERROR(__xludf.DUMMYFUNCTION("""COMPUTED_VALUE"""),"٠ سے ١٠ کے پیمانے پر، امام نے اپنے بیان میں کس حد تک عورتوں کے حقوق کی اہمیت کے خلاف بات کی (مثال کے طور پر خواتین کی تعلیم، ملازمت یا آزادی کی تنقید کی ہو)؟") -> ٠ سے ١٠ کے پیمانے پر، امام نے اپنے بیان میں کس حد تک عورتوں کے حقوق کی اہمیت کے خلاف بات کی (مثال کے طور پر خواتین کی تعلیم، ملازمت یا آزادی کی تنقید کی ہو)؟ | U1: =IFERROR(__xludf.DUMMYFUNCTION("""COMPUTED_VALUE"""),"٠ سے ١٠ کے پیمانے پر، امام نے اپنے بیان میں کس حد تک پڑوسیوں کے حقوق کی اہمیت کے خلاف بات کی (مثال کے طور پر پڑوسیوں یا پڑوس کی صفائی کی اہمیت کی تنقید کی ہو)؟") -> ٠ سے ١٠ کے پیمانے پر، امام نے اپنے بیان میں کس حد تک پڑوسیوں کے حقوق کی اہمیت کے خلاف بات کی (مثال کے طور پر پڑوسیوں یا پڑوس کی صفائی کی اہمیت کی تنقید کی ہو)؟ | V1: =IFERROR(__xludf.DUMMYFUNCTION("""COMPUTED_VALUE"""),"امام نے جو بیان دیا اسکا موضوع کیا تھا؟") -> امام نے جو بیان دیا اسکا موضوع کیا تھا؟ | W1: =IFERROR(__xludf.DUMMYFUNCTION("""COMPUTED_VALUE"""),"دو جملوں میں خلاصہ کریں کہ امام نے اپنے بیان میں کیا بات کی؟") -> دو جملوں میں خلاصہ کریں کہ امام نے اپنے بیان میں کیا بات کی؟ | X1: =IFERROR(__xludf.DUMMYFUNCTION("""COMPUTED_VALUE"""),"٠ سے ١٠ کے پیمانے پر،امام نےبیان میں حقوق اللّہ پر کس حد تک گفتگو کی (جیسے کہ نماز، حج اور روزے کی اہمیت)؟") -> ٠ سے ١٠ کے پیمانے پر،امام نےبیان میں حقوق اللّہ پر کس حد تک گفتگو کی (جیسے کہ نماز، حج اور روزے کی اہمیت)؟ | Y1: =IFERROR(__xludf.DUMMYFUNCTION("""COMPUTED_VALUE"""),"٠ سے ١٠ کے پیمانے پر،امام نےبیان میں حقوق العباد پر کس حد تک گفتگو کی (جیسے کہ دوسروں، معاشرے، یا قوم کے حقوق)؟") -> ٠ سے ١٠ کے پیمانے پر،امام نےبیان میں حقوق العباد پر کس حد تک گفتگو کی (جیسے کہ دوسروں، معاشرے، یا قوم کے حقوق)؟ | Z1: =IFERROR(__xludf.DUMMYFUNCTION("""COMPUTED_VALUE"""),"٠ سے ١٠ کے پیمانے پر،امام نے بیان میں سماجی موضوعات یا مسائل پر کس حد تک بات کی؟") -> ٠ سے ١٠ کے پیمانے پر،امام نے بیان میں سماجی موضوعات یا مسائل پر کس حد تک بات کی؟ | AA1: =IFERROR(__xludf.DUMMYFUNCTION("""COMPUTED_VALUE"""),"٠ سے ١٠ کے پیمانے پر،امام نے بیان میں مذہبی موضوعات پر کس حد تک بات کی؟") -> ٠ سے ١٠ کے پیمانے پر،امام نے بیان میں مذہبی موضوعات پر کس حد تک بات کی؟ | AB1: =IFERROR(__xludf.DUMMYFUNCTION("""COMPUTED_VALUE"""),"٠ سے ١٠ کے پیمانے پر، امام نے اپنے بیان میں تاریخی موضوعات پر کس حد تک گفتگو کی؟") -> ٠ سے ١٠ کے پیمانے پر، امام نے اپنے بیان میں تاریخی موضوعات پر کس حد تک گفتگو کی؟ | AC1: =IFERROR(__xludf.DUMMYFUNCTION("""COMPUTED_VALUE"""),"٠ سے ١٠ کے پیمانے پر، امام نے اپنے بیان میں سیاسی موضوعات پر کس حد تک گفتگو کی؟") -> ٠ سے ١٠ کے پیمانے پر، امام نے اپنے بیان میں سیاسی موضوعات پر کس حد تک گفتگو کی؟ | AD1: =IFERROR(__xludf.DUMMYFUNCTION("""COMPUTED_VALUE"""),"٠ سے ١٠ کے پیمانے پر، امام نے اپنے بیان میں اقتصادی موضوعات پر کس حد تک گفتگو کی؟") -> ٠ سے ١٠ کے پیمانے پر، امام نے اپنے بیان میں اقتصادی موضوعات پر کس حد تک گفتگو کی؟ | AE1: =IFERROR(__xludf.DUMMYFUNCTION("""COMPUTED_VALUE"""),"٠ سے ١٠ کے پیمانے پر، امام نے اپنے بیان میں مذہبی اقلیتوں کے بارے میں کس حد تک گفتگو کی؟") -> ٠ سے ١٠ کے پیمانے پر، امام نے اپنے بیان میں مذہبی اقلیتوں کے بارے میں کس حد تک گفتگو کی؟ | AF1: =IFERROR(__xludf.DUMMYFUNCTION("""COMPUTED_VALUE"""),"٠ سے ١٠ کے پیمانے پر، امام کا بیان کس حد تک قدامت پسند تھا؟") -> ٠ سے ١٠ کے پیمانے پر، امام کا بیان کس حد تک قدامت پسند تھا؟ | AG1: =IFERROR(__xludf.DUMMYFUNCTION("""COMPUTED_VALUE"""),"٠ سے ١٠ کے پیمانے پر، امام کا بیان کتنا خوش مزاج تھا اور لوگوں میں مثبت اثر رکھتا ہے؟") -> ٠ سے ١٠ کے پیمانے پر، امام کا بیان کتنا خوش مزاج تھا اور لوگوں میں مثبت اثر رکھتا ہے؟ | AH1: =IFERROR(__xludf.DUMMYFUNCTION("""COMPUTED_VALUE"""),"٠ سے ١٠ کے پیمانے پر، امام کے بیان میں کس حد تک نفرت انگیز باتیں تھیں؟") -> ٠ سے ١٠ کے پیمانے پر، امام کے بیان میں کس حد تک نفرت انگیز باتیں تھیں؟ | AI1: =IFERROR(__xludf.DUMMYFUNCTION("""COMPUTED_VALUE"""),"٠ سے ١٠ کے پیمانے پر، امام کے بیان کا مجموعی معیار کیسا تھا؟") -> ٠ سے ١٠ کے پیمانے پر، امام کے بیان کا مجموعی معیار کیسا تھا؟ | AJ1: =IFERROR(__xludf.DUMMYFUNCTION("""COMPUTED_VALUE"""),"بیان کا متن جو آپ نے لکھا ہے اسے یہاں اپلوڈ کریں-") -> بیان کا متن جو آپ نے لکھا ہے اسے یہاں اپلوڈ کریں- | AK1: =IFERROR(__xludf.DUMMYFUNCTION("""COMPUTED_VALUE"""),"اگر آپ ہمیں اضافی معلومات فراہم کرنا چاہتے ہیں یا آپ کو کوئی پریشانی ہے تو براہ کرم اسے نیچے لکھیں۔") -> اگر آپ ہمیں اضافی معلومات فراہم کرنا چاہتے ہیں یا آپ کو کوئی پریشانی ہے تو براہ کرم اسے نیچے لکھیں۔ | AL1: =IFERROR(__xludf.DUMMYFUNCTION("""COMPUTED_VALUE"""),"غور سے اس رسم الخط کو پڑھیں جو ہم نے آپ کو پڑھنے کے لیے دی تھی۔ درج ذیل سوالات آپ سے اس رسم الخط کا موازنہ امام کے جمعہ کے بیان سے کرنے کو کہیں گے۔ کیا آپ نے یہ رسم الخط پڑھ لیا ہے؟") -> غور سے اس رسم الخط کو پڑھیں جو ہم نے آپ کو پڑھنے کے لیے دی تھی۔ درج ذیل سوالات آپ سے اس رسم الخط کا موازنہ امام کے جمعہ کے بیان سے کرنے کو کہیں گے۔ کیا آپ نے یہ رسم الخط پڑھ لیا ہے؟ | AM1: =IFERROR(__xludf.DUMMYFUNCTION("""COMPUTED_VALUE"""),"امام نے دیے ہوۓ رسم الخط کے کتنے فیصد مواد پر بات کی؟ اگر امام نے رسم الخط کے مواد پر بالکل بات نہیں کی تو 0% لکھیں. اگر امام نے سارے مواد پر بات کی تو 100% لکھیں- ") -> امام نے دیے ہوۓ رسم الخط کے کتنے فیصد مواد پر بات کی؟ اگر امام نے رسم الخط کے مواد پر بالکل بات نہیں کی تو 0% لکھیں. اگر امام نے سارے مواد پر بات کی تو 100% لکھیں- | AN1: =IFERROR(__xludf.DUMMYFUNCTION("""COMPUTED_VALUE"""),"خطبہ نمبر اگر آپ خطبہ نمبر نہیں جانتے تو براہ کرم ٹیم سے تصدیق کریں اور پھر یہاں پر کریں۔") -> خطبہ نمبر اگر آپ خطبہ نمبر نہیں جانتے تو براہ کرم ٹیم سے تصدیق کریں اور پھر یہاں پر کریں۔ | AO1: Week # | AX1: Week #
A2: 1 | B2: =IFERROR(__xludf.DUMMYFUNCTION("""COMPUTED_VALUE"""),45679.888320625) -> 45679.888 | C2: =IFERROR(__xludf.DUMMYFUNCTION("""COMPUTED_VALUE"""),"Nsjsj") -> Nsjsj | D2: =IFERROR(__xludf.DUMMYFUNCTION("""COMPUTED_VALUE"""),"Dhjd") -> Dhjd | E2: =IFERROR(__xludf.DUMMYFUNCTION("""COMPUTED_VALUE"""),"Hejd") -> Hejd | F2: =IFERROR(__xludf.DUMMYFUNCTION("""COMPUTED_VALUE"""),"Hehej") -> Hehej | G2: =IFERROR(__xludf.DUMMYFUNCTION("""COMPUTED_VALUE"""),"Yes") -> Yes | H2: =IFERROR(__xludf.DUMMYFUNCTION("""COMPUTED_VALUE"""),6.0) -> 6 | I2: =IFERROR(__xludf.DUMMYFUNCTION("""COMPUTED_VALUE"""),4.0) -> 4 | J2: =IFERROR(__xludf.DUMMYFUNCTION("""COMPUTED_VALUE"""),4.0) -> 4 | K2: =IFERROR(__xludf.DUMMYFUNCTION("""COMPUTED_VALUE"""),3.0) -> 3 | L2: =IFERROR(__xludf.DUMMYFUNCTION("""COMPUTED_VALUE"""),3.0) -> 3 | M2: =IFERROR(__xludf.DUMMYFUNCTION("""COMPUTED_VALUE"""),4.0) -> 4 | N2: =IFERROR(__xludf.DUMMYFUNCTION("""COMPUTED_VALUE"""),3.0) -> 3 | O2: =IFERROR(__xludf.DUMMYFUNCTION("""COMPUTED_VALUE"""),3.0) -> 3 | P2: =IFERROR(__xludf.DUMMYFUNCTION("""COMPUTED_VALUE"""),2.0) -> 2 | Q2: =IFERROR(__xludf.DUMMYFUNCTION("""COMPUTED_VALUE"""),"No") -> No | R2: =IFERROR(__xludf.DUMMYFUNCTION("""COMPUTED_VALUE"""),"No") -> No | S2: =IFERROR(__xludf.DUMMYFUNCTION("""COMPUTED_VALUE"""),"No") -> No | T2: =IFERROR(__xludf.DUMMYFUNCTION("""COMPUTED_VALUE"""),7.0) -> 7 | U2: =IFERROR(__xludf.DUMMYFUNCTION("""COMPUTED_VALUE"""),4.0) -> 4 | V2: =IFERROR(__xludf.DUMMYFUNCTION("""COMPUTED_VALUE"""),"Hejs") -> Hejs | W2: =IFERROR(__xludf.DUMMYFUNCTION("""COMPUTED_VALUE"""),"Nsjss") -> Nsjss | X2: =IFERROR(__xludf.DUMMYFUNCTION("""COMPUTED_VALUE"""),7.0) -> 7 | Y2: =IFERROR(__xludf.DUMMYFUNCTION("""COMPUTED_VALUE"""),4.0) -> 4 | Z2: =IFERROR(__xludf.DUMMYFUNCTION("""COMPUTED_VALUE"""),4.0) -> 4 | AA2: =IFERROR(__xludf.DUMMYFUNCTION("""COMPUTED_VALUE"""),3.0) -> 3 | AB2: =IFERROR(__xludf.DUMMYFUNCTION("""COMPUTED_VALUE"""),4.0) -> 4 | AC2: =IFERROR(__xludf.DUMMYFUNCTION("""COMPUTED_VALUE"""),4.0) -> 4 | AD2: =IFERROR(__xludf.DUMMYFUNCTION("""COMPUTED_VALUE"""),6.0) -> 6 | AE2: =IFERROR(__xludf.DUMMYFUNCTION("""COMPUTED_VALUE"""),4.0) -> 4 | AF2: =IFERROR(__xludf.DUMMYFUNCTION("""COMPUTED_VALUE"""),5.0) -> 5 | AG2: =IFERROR(__xludf.DUMMYFUNCTION("""COMPUTED_VALUE"""),4.0) -> 4 | AH2: =IFERROR(__xludf.DUMMYFUNCTION("""COMPUTED_VALUE"""),4.0) -> 4 | AI2: =IFERROR(__xludf.DUMMYFUNCTION("""COMPUTED_VALUE"""),5.0) -> 5 | AJ2: =IFERROR(__xludf.DUMMYFUNCTION("""COMPUTED_VALUE"""),"https://drive.google.com/open?id=1vKJTUA9SN120dU9My0de-0Lpk6Hd9q-y") -> https://drive.google.com/open?id=1vKJTUA9SN120dU9My0de-0Lpk6Hd9q-y | AO2: Delete
A3: 2 | B3: =IFERROR(__xludf.DUMMYFUNCTION("""COMPUTED_VALUE"""),45686.550617071756) -> 45686.551 | C3: =IFERROR(__xludf.DUMMYFUNCTION("""COMPUTED_VALUE"""),"Jj") -> Jj | D3: =IFERROR(__xludf.DUMMYFUNCTION("""COMPUTED_VALUE"""),"Jkk") -> Jkk | E3: =IFERROR(__xludf.DUMMYFUNCTION("""COMPUTED_VALUE"""),"Kjhh") -> Kjhh | F3: =IFERROR(__xludf.DUMMYFUNCTION("""COMPUTED_VALUE"""),"Iiu") -> Iiu | G3: =IFERROR(__xludf.DUMMYFUNCTION("""COMPUTED_VALUE"""),"Yes") -> Yes | H3: =IFERROR(__xludf.DUMMYFUNCTION("""COMPUTED_VALUE"""),4.0) -> 4 | I3: =IFERROR(__xludf.DUMMYFUNCTION("""COMPUTED_VALUE"""),4.0) -> 4 | J3: =IFERROR(__xludf.DUMMYFUNCTION("""COMPUTED_VALUE"""),6.0) -> 6 | K3: =IFERROR(__xludf.DUMMYFUNCTION("""COMPUTED_VALUE"""),3.0) -> 3 | L3: =IFERROR(__xludf.DUMMYFUNCTION("""COMPUTED_VALUE"""),3.0) -> 3 | M3: =IFERROR(__xludf.DUMMYFUNCTION("""COMPUTED_VALUE"""),2.0) -> 2 | N3: =IFERROR(__xludf.DUMMYFUNCTION("""COMPUTED_VALUE"""),3.0) -> 3 | O3: =IFERROR(__xludf.DUMMYFUNCTION("""COMPUTED_VALUE"""),4.0) -> 4 | P3: =IFERROR(__xludf.DUMMYFUNCTION("""COMPUTED_VALUE"""),4.0) -> 4 | Q3: =IFERROR(__xludf.DUMMYFUNCTION("""COMPUTED_VALUE"""),"No") -> No | R3: =IFERROR(__xludf.DUMMYFUNCTION("""COMPUTED_VALUE"""),"No") -> No | S3: =IFERROR(__xludf.DUMMYFUNCTION("""COMPUTED_VALUE"""),"No") -> No | T3: =IFERROR(__xludf.DUMMYFUNCTION("""COMPUTED_VALUE"""),0.0) -> 0 | U3: =IFERROR(__xludf.DUMMYFUNCTION("""COMPUTED_VALUE"""),0.0) -> 0 | V3: =IFERROR(__xludf.DUMMYFUNCTION("""COMPUTED_VALUE"""),"Bhvv") -> Bhvv | W3: =IFERROR(__xludf.DUMMYFUNCTION("""COMPUTED_VALUE"""),"Uhh") -> Uhh | X3: =IFERROR(__xludf.DUMMYFUNCTION("""COMPUTED_VALUE"""),2.0) -> 2 | Y3: =IFERROR(__xludf.DUMMYFUNCTION("""COMPUTED_VALUE"""),4.0) -> 4 | Z3: =IFERROR(__xludf.DUMMYFUNCTION("""COMPUTED_VALUE"""),5.0) -> 5 | AA3: =IFERROR(__xludf.DUMMYFUNCTION("""COMPUTED_VALUE"""),3.0) -> 3 | AB3: =IFERROR(__xludf.DUMMYFUNCTION("""COMPUTED_VALUE"""),4.0) -> 4 | AC3: =IFERROR(__xludf.DUMMYFUNCTION("""COMPUTED_VALUE"""),5.0) -> 5 | AD3: =IFERROR(__xludf.DUMMYFUNCTION("""COMPUTED_VALUE"""),4.0) -> 4 | AE3: =IFERROR(__xludf.DUMMYFUNCTION("""COMPUTED_VALUE"""),4.0) -> 4 | AF3: =IFERROR(__xludf.DUMMYFUNCTION("""COMPUTED_VALUE"""),5.0) -> 5 | AG3: =IFERROR(__xludf.DUMMYFUNCTION("""COMPUTED_VALUE"""),4.0) -> 4 | AH3: =IFERROR(__xludf.DUMMYFUNCTION("""COMPUTED_VALUE"""),4.0) -> 4 | AI3: =IFERROR(__xludf.DUMMYFUNCTION("""COMPUTED_VALUE"""),4.0) -> 4 | AO3: Delete
A4: 3 | B4: =IFERROR(__xludf.DUMMYFUNCTION("""COMPUTED_VALUE"""),45688.360408113425) -> 45688.36 | C4: =IFERROR(__xludf.DUMMYFUNCTION("""COMPUTED_VALUE"""),"Nadir Ali ") -> Nadir Ali | D4: =IFERROR(__xludf.DUMMYFUNCTION("""COMPUTED_VALUE"""),"03006581830") -> 03006581830 | E4: =IFERROR(__xludf.DUMMYFUNCTION("""COMPUTED_VALUE"""),"Jamia Masjid Shah Jamal") -> Jamia Masjid Shah Jamal | F4: =IFERROR(__xludf.DUMMYFUNCTION("""COMPUTED_VALUE"""),"WZJKX") -> WZJKX | G4: =IFERROR(__xludf.DUMMYFUNCTION("""COMPUTED_VALUE"""),"No") -> No | K4: =IFERROR(__xludf.DUMMYFUNCTION("""COMPUTED_VALUE"""),0.0) -> 0 | L4: =IFERROR(__xludf.DUMMYFUNCTION("""COMPUTED_VALUE"""),0.0) -> 0 | M4: =IFERROR(__xludf.DUMMYFUNCTION("""COMPUTED_VALUE"""),0.0) -> 0 | N4: =IFERROR(__xludf.DUMMYFUNCTION("""COMPUTED_VALUE"""),0.0) -> 0 | O4: =IFERROR(__xludf.DUMMYFUNCTION("""COMPUTED_VALUE"""),0.0) -> 0 | P4: =IFERROR(__xludf.DUMMYFUNCTION("""COMPUTED_VALUE"""),0.0) -> 0 | Q4: =IFERROR(__xludf.DUMMYFUNCTION("""COMPUTED_VALUE"""),"No") -> No | R4: =IFERROR(__xludf.DUMMYFUNCTION("""COMPUTED_VALUE"""),"No") -> No | S4: =IFERROR(__xludf.DUMMYFUNCTION("""COMPUTED_VALUE"""),"No") -> No | T4: =IFERROR(__xludf.DUMMYFUNCTION("""COMPUTED_VALUE"""),0.0) -> 0 | U4: =IFERROR(__xludf.DUMMYFUNCTION("""COMPUTED_VALUE"""),0.0) -> 0 | V4: =IFERROR(__xludf.DUMMYFUNCTION("""COMPUTED_VALUE"""),"معراج ") -> معراج | W4: =IFERROR(__xludf.DUMMYFUNCTION("""COMPUTED_VALUE"""),"معراج پر جانے کا واقع بیان کیا") -> معراج پر جانے کا واقع بیان کیا | X4: =IFERROR(__xludf.DUMMYFUNCTION("""COMPUTED_VALUE"""),0.0) -> 0 | Y4: =IFERROR(__xludf.DUMMYFUNCTION("""COMPUTED_VALUE"""),3.0) -> 3 | Z4: =IFERROR(__xludf.DUMMYFUNCTION("""COMPUTED_VALUE"""),4.0) -> 4 | AA4: =IFERROR(__xludf.DUMMYFUNCTION("""COMPUTED_VALUE"""),7.0) -> 7 | AB4: =IFERROR(__xludf.DUMMYFUNCTION("""COMPUTED_VALUE"""),6.0) -> 6 | AC4: =IFERROR(__xludf.DUMMYFUNCTION("""COMPUTED_VALUE"""),0.0) -> 0 | AD4: =IFERROR(__xludf.DUMMYFUNCTION("""COMPUTED_VALUE"""),0.0) -> 0 | AE4: =IFERROR(__xludf.DUMMYFUNCTION("""COMPUTED_VALUE"""),0.0) -> 0 | AF4: =IFERROR(__xludf.DUMMYFUNCTION("""COMPUTED_VALUE"""),6.0) -> 6 | AG4: =IFERROR(__xludf.DUMMYFUNCTION("""COMPUTED_VALUE"""),7.0) -> 7 | AH4: =IFERROR(__xludf.DUMMYFUNCTION("""COMPUTED_VALUE"""),0.0) -> 0 | AI4: =IFERROR(__xludf.DUMMYFUNCTION("""COMPUTED_VALUE"""),7.0) -> 7 | AJ4: =IFERROR(__xludf.DUMMYFUNCTION("""COMPUTED_VALUE"""),"https://drive.google.com/open?id=1KkDFdV27Kv6kG_rPKmgHkIj3QyUZ5kPJ") -> https://drive.google.com/open?id=1KkDFdV27Kv6kG_rPKmgHkIj3QyUZ5kPJ | AO4: 1 | AX4: 1
A5: 4 | B5: =IFERROR(__xludf.DUMMYFUNCTION("""COMPUTED_VALUE"""),45689.35042928241) -> 45689.35 | C5: =IFERROR(__xludf.DUMMYFUNCTION("""COMPUTED_VALUE"""),"Abdul Qayyum ") -> Abdul Qayyum | D5: =IFERROR(__xludf.DUMMYFUNCTION("""COMPUTED_VALUE"""),"03257598827") -> 03257598827 | E5: =IFERROR(__xludf.DUMMYFUNCTION("""COMPUTED_VALUE"""),"Jamia Masjid Takiya Puter Nagha Lahore") -> Jamia Masjid Takiya Puter Nagha Lahore | F5: =IFERROR(__xludf.DUMMYFUNCTION("""COMPUTED_VALUE"""),"ZTLCN") -> ZTLCN | G5: =IFERROR(__xludf.DUMMYFUNCTION("""COMPUTED_VALUE"""),"Yes") -> Yes | H5: =IFERROR(__xludf.DUMMYFUNCTION("""COMPUTED_VALUE"""),9.0) -> 9 | I5: =IFERROR(__xludf.DUMMYFUNCTION("""COMPUTED_VALUE"""),1.0) -> 1 | J5: =IFERROR(__xludf.DUMMYFUNCTION("""COMPUTED_VALUE"""),8.0) -> 8 | K5: =IFERROR(__xludf.DUMMYFUNCTION("""COMPUTED_VALUE"""),8.0) -> 8 | L5: =IFERROR(__xludf.DUMMYFUNCTION("""COMPUTED_VALUE"""),0.0) -> 0 | M5: =IFERROR(__xludf.DUMMYFUNCTION("""COMPUTED_VALUE"""),7.0) -> 7 | N5: =IFERROR(__xludf.DUMMYFUNCTION("""COMPUTED_VALUE"""),0.0) -> 0 | O5: =IFERROR(__xludf.DUMMYFUNCTION("""COMPUTED_VALUE"""),8.0) -> 8 | P5: =IFERROR(__xludf.DUMMYFUNCTION("""COMPUTED_VALUE"""),0.0) -> 0 | Q5: =IFERROR(__xludf.DUMMYFUNCTION("""COMPUTED_VALUE"""),"Yes") -> Yes | R5: =IFERROR(__xludf.DUMMYFUNCTION("""COMPUTED_VALUE"""),"No") -> No | S5: =IFERROR(__xludf.DUMMYFUNCTION("""COMPUTED_VALUE"""),"Yes") -> Yes | T5: =IFERROR(__xludf.DUMMYFUNCTION("""COMPUTED_VALUE"""),0.0) -> 0 | U5: =IFERROR(__xludf.DUMMYFUNCTION("""COMPUTED_VALUE"""),0.0) -> 0 | V5: =IFERROR(__xludf.DUMMYFUNCTION("""COMPUTED_VALUE"""),"Auraton ky Haqooq aur Taleem-o-Tarbiyat") -> Auraton ky Haqooq aur Taleem-o-Tarbiyat | W5: =IFERROR(__xludf.DUMMYFUNCTION("""COMPUTED_VALUE"""),"Respect of Women Education of women Rights of Women ") -> Respect of Women Education of women Rights of Women | X5: =IFERROR(__xludf.DUMMYFUNCTION("""COMPUTED_VALUE"""),0.0) -> 0 | Y5: =IFERROR(__xludf.DUMMYFUNCTION("""COMPUTED_VALUE"""),0.0) -> 0 | Z5: =IFERROR(__xludf.DUMMYFUNCTION("""COMPUTED_VALUE"""),0.0) -> 0 | AA5: =IFERROR(__xludf.DUMMYFUNCTION("""COMPUTED_VALUE"""),2.0) -> 2 | AB5: =IFERROR(__xludf.DUMMYFUNCTION("""COMPUTED_VALUE"""),1.0) -> 1 | AC5: =IFERROR(__xludf.DUMMYFUNCTION("""COMPUTED_VALUE"""),0.0) -> 0 | AD5: =IFERROR(__xludf.DUMMYFUNCTION("""COMPUTED_VALUE"""),1.0) -> 1 | AE5: =IFERROR(__xludf.DUMMYFUNCTION("""COMPUTED_VALUE"""),0.0) -> 0 | AF5: =IFERROR(__xludf.DUMMYFUNCTION("""COMPUTED_VALUE"""),0.0) -> 0 | AG5: =IFERROR(__xludf.DUMMYFUNCTION("""COMPUTED_VALUE"""),6.0) -> 6 | AH5: =IFERROR(__xludf.DUMMYFUNCTION("""COMPUTED_VALUE"""),0.0) -> 0 | AI5: =IFERROR(__xludf.DUMMYFUNCTION("""COMPUTED_VALUE"""),8.0) -> 8 | AJ5: =IFERROR(__xludf.DUMMYFUNCTION("""COMPUTED_VALUE"""),"https://drive.google.com/open?id=1CrhWG--K7K7mYhRjUYMPQlqZoGx7TFD1") -> https://drive.google.com/open?id=1CrhWG--K7K7mYhRjUYMPQlqZoGx7TFD1 | AK5: =IFERROR(__xludf.DUMMYFUNCTION("""COMPUTED_VALUE"""),"No") -> No | AO5: 1 | AX5: 1
A6: 5 | B6: =IFERROR(__xludf.DUMMYFUNCTION("""COMPUTED_VALUE"""),45689.65577814815) -> 45689.656 | C6: =IFERROR(__xludf.DUMMYFUNCTION("""COMPUTED_VALUE"""),"Abdul Rauf ") -> Abdul Rauf | D6: =IFERROR(__xludf.DUMMYFUNCTION("""COMPUTED_VALUE"""),"03008789090") -> 03008789090 | E6: =IFERROR(__xludf.DUMMYFUNCTION("""COMPUTED_VALUE"""),"Masjid Allah joya ") -> Masjid Allah joya | F6: =IFERROR(__xludf.DUMMYFUNCTION("""COMPUTED_VALUE"""),"ZBRWJ") -> ZBRWJ | G6: =IFERROR(__xludf.DUMMYFUNCTION("""COMPUTED_VALUE"""),"Yes") -> Yes | H6: =IFERROR(__xludf.DUMMYFUNCTION("""COMPUTED_VALUE"""),8.0) -> 8 | I6: =IFERROR(__xludf.DUMMYFUNCTION("""COMPUTED_VALUE"""),7.0) -> 7 | J6: =IFERROR(__xludf.DUMMYFUNCTION("""COMPUTED_VALUE"""),9.0) -> 9 | K6: =IFERROR(__xludf.DUMMYFUNCTION("""COMPUTED_VALUE"""),3.0) -> 3 | L6: =IFERROR(__xludf.DUMMYFUNCTION("""COMPUTED_VALUE"""),7.0) -> 7 | M6: =IFERROR(__xludf.DUMMYFUNCTION("""COMPUTED_VALUE"""),6.0) -> 6 | N6: =IFERROR(__xludf.DUMMYFUNCTION("""COMPUTED_VALUE"""),5.0) -> 5 | O6: =IFERROR(__xludf.DUMMYFUNCTION("""COMPUTED_VALUE"""),8.0) -> 8 | P6: =IFERROR(__xludf.DUMMYFUNCTION("""COMPUTED_VALUE"""),7.0) -> 7 | Q6: =IFERROR(__xludf.DUMMYFUNCTION("""COMPUTED_VALUE"""),"Yes") -> Yes | R6: =IFERROR(__xludf.DUMMYFUNCTION("""COMPUTED_VALUE"""),"Yes") -> Yes | S6: =IFERROR(__xludf.DUMMYFUNCTION("""COMPUTED_VALUE"""),"Yes") -> Yes | T6: =IFERROR(__xludf.DUMMYFUNCTION("""COMPUTED_VALUE"""),0.0) -> 0 | U6: =IFERROR(__xludf.DUMMYFUNCTION("""COMPUTED_VALUE"""),0.0) -> 0 | V6: =IFERROR(__xludf.DUMMYFUNCTION("""COMPUTED_VALUE"""),"Rights of Neighbors ") -> Rights of Neighbors | W6: =IFERROR(__xludf.DUMMYFUNCTION("""COMPUTED_VALUE"""),"Importantance of Neighbors ") -> Importantance of Neighbors | X6: =IFERROR(__xludf.DUMMYFUNCTION("""COMPUTED_VALUE"""),1.0) -> 1 | Y6: =IFERROR(__xludf.DUMMYFUNCTION("""COMPUTED_VALUE"""),8.0) -> 8 | Z6: =IFERROR(__xludf.DUMMYFUNCTION("""COMPUTED_VALUE"""),8.0) -> 8 | AA6: =IFERROR(__xludf.DUMMYFUNCTION("""COMPUTED_VALUE"""),7.0) -> 7 | AB6: =IFERROR(__xludf.DUMMYFUNCTION("""COMPUTED_VALUE"""),6.0) -> 6 | AC6: =IFERROR(__xludf.DUMMYFUNCTION("""COMPUTED_VALUE"""),0.0) -> 0 | AD6: =IFERROR(__xludf.DUMMYFUNCTION("""COMPUTED_VALUE"""),1.0) -> 1 | AE6: =IFERROR(__xludf.DUMMYFUNCTION("""COMPUTED_VALUE"""),0.0) -> 0 | AF6: =IFERROR(__xludf.DUMMYFUNCTION("""COMPUTED_VALUE"""),6.0) -> 6 | AG6: =IFERROR(__xludf.DUMMYFUNCTION("""COMPUTED_VALUE"""),9.0) -> 9 | AH6: =IFERROR(__xludf.DUMMYFUNCTION("""COMPUTED_VALUE"""),0.0) -> 0 | AI6: =IFERROR(__xludf.DUMMYFUNCTION("""COMPUTED_VALUE"""),8.0) -> 8 | AJ6: =IFERROR(__xludf.DUMMYFUNCTION("""COMPUTED_VALUE"""),"https://drive.google.com/open?id=15WbhlARN4Y3XFA7StPTASakDWlk0VyEl") -> https://drive.google.com/open?id=15WbhlARN4Y3XFA7StPTASakDWlk0VyEl | AK6: =IFERROR(__xludf.DUMMYFUNCTION("""COMPUTED_VALUE"""),"No") -> No | AO6: 1 | AX6: 1
A7: 6 | B7: =IFERROR(__xludf.DUMMYFUNCTION("""COMPUTED_VALUE"""),45693.244078310185) -> 45693.244 | C7: =IFERROR(__xludf.DUMMYFUNCTION("""COMPUTED_VALUE"""),"Bilal") -> Bilal | D7: =IFERROR(__xludf.DUMMYFUNCTION("""COMPUTED_VALUE"""),"03066761947") -> 03066761947 | E7: =IFERROR(__xludf.DUMMYFUNCTION("""COMPUTED_VALUE"""),"Jama masjid Bhohaar wali lahore gate") -> Jama masjid Bhohaar wali lahore gate | F7: =IFERROR(__xludf.DUMMYFUNCTION("""COMPUTED_VALUE"""),"oonhe") -> oonhe | G7: =IFERROR(__xludf.DUMMYFUNCTION("""COMPUTED_VALUE"""),"Yes") -> Yes | H7: =IFERROR(__xludf.DUMMYFUNCTION("""COMPUTED_VALUE"""),8.0) -> 8 | I7: =IFERROR(__xludf.DUMMYFUNCTION("""COMPUTED_VALUE"""),6.0) -> 6 | J7: =IFERROR(__xludf.DUMMYFUNCTION("""COMPUTED_VALUE"""),7.0) -> 7 | K7: =IFERROR(__xludf.DUMMYFUNCTION("""COMPUTED_VALUE"""),7.0) -> 7 | L7: =IFERROR(__xludf.DUMMYFUNCTION("""COMPUTED_VALUE"""),5.0) -> 5 | M7: =IFERROR(__xludf.DUMMYFUNCTION("""COMPUTED_VALUE"""),7.0) -> 7 | N7: =IFERROR(__xludf.DUMMYFUNCTION("""COMPUTED_VALUE"""),8.0) -> 8 | O7: =IFERROR(__xludf.DUMMYFUNCTION("""COMPUTED_VALUE"""),8.0) -> 8 | P7: =IFERROR(__xludf.DUMMYFUNCTION("""COMPUTED_VALUE"""),4.0) -> 4 | Q7: =IFERROR(__xludf.DUMMYFUNCTION("""COMPUTED_VALUE"""),"Yes") -> Yes | R7: =IFERROR(__xludf.DUMMYFUNCTION("""COMPUTED_VALUE"""),"Yes") -> Yes | S7: =IFERROR(__xludf.DUMMYFUNCTION("""COMPUTED_VALUE"""),"No") -> No | T7: =IFERROR(__xludf.DUMMYFUNCTION("""COMPUTED_VALUE"""),0.0) -> 0 | U7: =IFERROR(__xludf.DUMMYFUNCTION("""COMPUTED_VALUE"""),4.0) -> 4 | V7: =IFERROR(__xludf.DUMMYFUNCTION("""COMPUTED_VALUE"""),"Parasuon k halooq") -> Parasuon k halooq | W7: =IFERROR(__xludf.DUMMYFUNCTION("""COMPUTED_VALUE"""),"Parasuon k halooq ") -> Parasuon k halooq | X7: =IFERROR(__xludf.DUMMYFUNCTION("""COMPUTED_VALUE"""),2.0) -> 2 | Y7: =IFERROR(__xludf.DUMMYFUNCTION("""COMPUTED_VALUE"""),3.0) -> 3 | Z7: =IFERROR(__xludf.DUMMYFUNCTION("""COMPUTED_VALUE"""),4.0) -> 4 | AA7: =IFERROR(__xludf.DUMMYFUNCTION("""COMPUTED_VALUE"""),3.0) -> 3 | AB7: =IFERROR(__xludf.DUMMYFUNCTION("""COMPUTED_VALUE"""),0.0) -> 0 | AC7: =IFERROR(__xludf.DUMMYFUNCTION("""COMPUTED_VALUE"""),2.0) -> 2 | AD7: =IFERROR(__xludf.DUMMYFUNCTION("""COMPUTED_VALUE"""),2.0) -> 2 | AE7: =IFERROR(__xludf.DUMMYFUNCTION("""COMPUTED_VALUE"""),0.0) -> 0 | AF7: =IFERROR(__xludf.DUMMYFUNCTION("""COMPUTED_VALUE"""),0.0) -> 0 | AG7: =IFERROR(__xludf.DUMMYFUNCTION("""COMPUTED_VALUE"""),10.0) -> 10 | AH7: =IFERROR(__xludf.DUMMYFUNCTION("""COMPUTED_VALUE"""),0.0) -> 0 | AI7: =IFERROR(__xludf.DUMMYFUNCTION("""COMPUTED_VALUE"""),10.0) -> 10 | AJ7: =IFERROR(__xludf.DUMMYFUNCTION("""COMPUTED_VALUE"""),"https://drive.google.com/open?id=1rAX0n3LUlDU_Um53O6ie9-wPvZE-Ubyj") -> https://drive.google.com/open?id=1rAX0n3LUlDU_Um53O6ie9-wPvZE-Ubyj | AK7: =IFERROR(__xludf.DUMMYFUNCTION("""COMPUTED_VALUE"""),"No") -> No | AO7: 1 | AX7: 1
A8: 7 | B8: =IFERROR(__xludf.DUMMYFUNCTION("""COMPUTED_VALUE"""),45693.36597701389) -> 45693.366 | C8: =IFERROR(__xludf.DUMMYFUNCTION("""COMPUTED_VALUE"""),"M Haseeb ") -> M Haseeb | D8: =IFERROR(__xludf.DUMMYFUNCTION("""COMPUTED_VALUE"""),"03262232424") -> 03262232424 | E8: =IFERROR(__xludf.DUMMYFUNCTION("""COMPUTED_VALUE"""),"Jamia masjid Abdul Ghani") -> Jamia masjid Abdul Ghani | F8: =IFERROR(__xludf.DUMMYFUNCTION("""COMPUTED_VALUE"""),"OIYZT") -> OIYZT | G8: =IFERROR(__xludf.DUMMYFUNCTION("""COMPUTED_VALUE"""),"Yes") -> Yes | H8: =IFERROR(__xludf.DUMMYFUNCTION("""COMPUTED_VALUE"""),9.0) -> 9 | I8: =IFERROR(__xludf.DUMMYFUNCTION("""COMPUTED_VALUE"""),1.0) -> 1 | J8: =IFERROR(__xludf.DUMMYFUNCTION("""COMPUTED_VALUE"""),9.0) -> 9 | K8: =IFERROR(__xludf.DUMMYFUNCTION("""COMPUTED_VALUE"""),3.0) -> 3 | L8: =IFERROR(__xludf.DUMMYFUNCTION("""COMPUTED_VALUE"""),9.0) -> 9 | M8: =IFERROR(__xludf.DUMMYFUNCTION("""COMPUTED_VALUE"""),0.0) -> 0 | N8: =IFERROR(__xludf.DUMMYFUNCTION("""COMPUTED_VALUE"""),9.0) -> 9 | O8: =IFERROR(__xludf.DUMMYFUNCTION("""COMPUTED_VALUE"""),0.0) -> 0 | P8: =IFERROR(__xludf.DUMMYFUNCTION("""COMPUTED_VALUE"""),0.0) -> 0 | Q8: =IFERROR(__xludf.DUMMYFUNCTION("""COMPUTED_VALUE"""),"No") -> No | R8: =IFERROR(__xludf.DUMMYFUNCTION("""COMPUTED_VALUE"""),"No") -> No | S8: =IFERROR(__xludf.DUMMYFUNCTION("""COMPUTED_VALUE"""),"No") -> No | T8: =IFERROR(__xludf.DUMMYFUNCTION("""COMPUTED_VALUE"""),0.0) -> 0 | U8: =IFERROR(__xludf.DUMMYFUNCTION("""COMPUTED_VALUE"""),0.0) -> 0 | V8: =IFERROR(__xludf.DUMMYFUNCTION("""COMPUTED_VALUE"""),"Parosioo ka haquq") -> Parosioo ka haquq | W8: =IFERROR(__xludf.DUMMYFUNCTION("""COMPUTED_VALUE"""),"Parosioo ka haquq or un ka sath husna saluk") -> Parosioo ka haquq or un ka sath husna saluk | X8: =IFERROR(__xludf.DUMMYFUNCTION("""COMPUTED_VALUE"""),0.0) -> 0 | Y8: =IFERROR(__xludf.DUMMYFUNCTION("""COMPUTED_VALUE"""),10.0) -> 10 | Z8: =IFERROR(__xludf.DUMMYFUNCTION("""COMPUTED_VALUE"""),0.0) -> 0 | AA8: =IFERROR(__xludf.DUMMYFUNCTION("""COMPUTED_VALUE"""),10.0) -> 10 | AB8: =IFERROR(__xludf.DUMMYFUNCTION("""COMPUTED_VALUE"""),0.0) -> 0 | AC8: =IFERROR(__xludf.DUMMYFUNCTION("""COMPUTED_VALUE"""),0.0) -> 0 | AD8: =IFERROR(__xludf.DUMMYFUNCTION("""COMPUTED_VALUE"""),0.0) -> 0 | AE8: =IFERROR(__xludf.DUMMYFUNCTION("""COMPUTED_VALUE"""),0.0) -> 0 | AF8: =IFERROR(__xludf.DUMMYFUNCTION("""COMPUTED_VALUE"""),9.0) -> 9 | AG8: =IFERROR(__xludf.DUMMYFUNCTION("""COMPUTED_VALUE"""),8.0) -> 8 | AH8: =IFERROR(__xludf.DUMMYFUNCTION("""COMPUTED_VALUE"""),0.0) -> 0 | AI8: =IFERROR(__xludf.DUMMYFUNCTION("""COMPUTED_VALUE"""),9.0) -> 9 | AJ8: =IFERROR(__xludf.DUMMYFUNCTION("""COMPUTED_VALUE"""),"https://drive.google.com/open?id=1KmOUD75NssVwphApVq7SZE-meTsh3bTJ") -> https://drive.google.com/open?id=1KmOUD75NssVwphApVq7SZE-meTsh3bTJ | AO8: 1 | AX8: 1
A9: 8 | B9: =IFERROR(__xludf.DUMMYFUNCTION("""COMPUTED_VALUE"""),45693.531949571756) -> 45693.532 | C9: =IFERROR(__xludf.DUMMYFUNCTION("""COMPUTED_VALUE"""),"Sheheryar Ahmad") -> Sheheryar Ahmad | D9: =IFERROR(__xludf.DUMMYFUNCTION("""COMPUTED_VALUE"""),"03194458854") -> 03194458854 | E9: =IFERROR(__xludf.DUMMYFUNCTION("""COMPUTED_VALUE"""),"Masjid Abu Bakar e Sadiq almarof Peshawari Masjid") -> Masjid Abu Bakar e Sadiq almarof Peshawari Masjid | F9: =IFERROR(__xludf.DUMMYFUNCTION("""COMPUTED_VALUE"""),"TELOU") -> TELOU | G9: =IFERROR(__xludf.DUMMYFUNCTION("""COMPUTED_VALUE"""),"Yes") -> Yes | H9: =IFERROR(__xludf.DUMMYFUNCTION("""COMPUTED_VALUE"""),8.0) -> 8 | I9: =IFERROR(__xludf.DUMMYFUNCTION("""COMPUTED_VALUE"""),3.0) -> 3 | J9: =IFERROR(__xludf.DUMMYFUNCTION("""COMPUTED_VALUE"""),8.0) -> 8 | K9: =IFERROR(__xludf.DUMMYFUNCTION("""COMPUTED_VALUE"""),9.0) -> 9 | L9: =IFERROR(__xludf.DUMMYFUNCTION("""COMPUTED_VALUE"""),0.0) -> 0 | M9: =IFERROR(__xludf.DUMMYFUNCTION("""COMPUTED_VALUE"""),10.0) -> 10 | N9: =IFERROR(__xludf.DUMMYFUNCTION("""COMPUTED_VALUE"""),0.0) -> 0 | O9: =IFERROR(__xludf.DUMMYFUNCTION("""COMPUTED_VALUE"""),10.0) -> 10 | P9: =IFERROR(__xludf.DUMMYFUNCTION("""COMPUTED_VALUE"""),0.0) -> 0 | Q9: =IFERROR(__xludf.DUMMYFUNCTION("""COMPUTED_VALUE"""),"Yes") -> Yes | R9: =IFERROR(__xludf.DUMMYFUNCTION("""COMPUTED_VALUE"""),"No") -> No | S9: =IFERROR(__xludf.DUMMYFUNCTION("""COMPUTED_VALUE"""),"Yes") -> Yes | T9: =IFERROR(__xludf.DUMMYFUNCTION("""COMPUTED_VALUE"""),10.0) -> 10 | U9: =IFERROR(__xludf.DUMMYFUNCTION("""COMPUTED_VALUE"""),0.0) -> 0 | V9: =IFERROR(__xludf.DUMMYFUNCTION("""COMPUTED_VALUE"""),"Women rights in Islam") -> Women rights in Islam | W9: =IFERROR(__xludf.DUMMYFUNCTION("""COMPUTED_VALUE"""),"Kahwateen kay sath acha rawaya rakhaya jay, unko taleem ka haq milay") -> Kahwateen kay sath acha rawaya rakhaya jay, unko taleem ka haq milay | X9: =IFERROR(__xludf.DUMMYFUNCTION("""COMPUTED_VALUE"""),0.0) -> 0 | Y9: =IFERROR(__xludf.DUMMYFUNCTION("""COMPUTED_VALUE"""),9.0) -> 9 | Z9: =IFERROR(__xludf.DUMMYFUNCTION("""COMPUTED_VALUE"""),9.0) -> 9 | AA9: =IFERROR(__xludf.DUMMYFUNCTION("""COMPUTED_VALUE"""),0.0) -> 0 | AB9: =IFERROR(__xludf.DUMMYFUNCTION("""COMPUTED_VALUE"""),9.0) -> 9 | AC9: =IFERROR(__xludf.DUMMYFUNCTION("""COMPUTED_VALUE"""),0.0) -> 0 | AD9: =IFERROR(__xludf.DUMMYFUNCTION("""COMPUTED_VALUE"""),4.0) -> 4 | AE9: =IFERROR(__xludf.DUMMYFUNCTION("""COMPUTED_VALUE"""),0.0) -> 0 | AF9: =IFERROR(__xludf.DUMMYFUNCTION("""COMPUTED_VALUE"""),10.0) -> 10 | AG9: =IFERROR(__xludf.DUMMYFUNCTION("""COMPUTED_VALUE"""),10.0) -> 10 | AH9: =IFERROR(__xludf.DUMMYFUNCTION("""COMPUTED_VALUE"""),0.0) -> 0 | AI9: =IFERROR(__xludf.DUMMYFUNCTION("""COMPUTED_VALUE"""),10.0) -> 10 | AJ9: =IFERROR(__xludf.DUMMYFUNCTION("""COMPUTED_VALUE"""),"https://drive.google.com/open?id=1K8dsFWgTQrLE0cl4SvBMENAQyNLUC7Si") -> https://drive.google.com/open?id=1K8dsFWgTQrLE0cl4SvBMENAQyNLUC7Si | AO9: was rejcted naya from mangwa lya tha updated redording ka | AX9: 1
A10: 9 | B10: =IFERROR(__xludf.DUMMYFUNCTION("""COMPUTED_VALUE"""),45694.05800422454) -> 45694.058 | C10: =IFERROR(__xludf.DUMMYFUNCTION("""COMPUTED_VALUE"""),"Babar Ali") -> Babar Ali | D10: =IFERROR(__xludf.DUMMYFUNCTION("""COMPUTED_VALUE"""),"03011297393") -> 03011297393 | E10: =IFERROR(__xludf.DUMMYFUNCTION("""COMPUTED_VALUE"""),"Jamia Masjid Shamas( jamia masjid darbar peer hadi rehnuma)") -> Jamia Masjid Shamas( jamia masjid darbar peer hadi rehnuma) | F10: =IFERROR(__xludf.DUMMYFUNCTION("""COMPUTED_VALUE"""),"Jeztx") -> Jeztx | G10: =IFERROR(__xludf.DUMMYFUNCTION("""COMPUTED_VALUE"""),"Yes") -> Yes | H10: =IFERROR(__xludf.DUMMYFUNCTION("""COMPUTED_VALUE"""),9.0) -> 9 | I10: =IFERROR(__xludf.DUMMYFUNCTION("""COMPUTED_VALUE"""),2.0) -> 2 | J10: =IFERROR(__xludf.DUMMYFUNCTION("""COMPUTED_VALUE"""),9.0) -> 9 | K10: =IFERROR(__xludf.DUMMYFUNCTION("""COMPUTED_VALUE"""),0.0) -> 0 | L10: =IFERROR(__xludf.DUMMYFUNCTION("""COMPUTED_VALUE"""),0.0) -> 0 | M10: =IFERROR(__xludf.DUMMYFUNCTION("""COMPUTED_VALUE"""),9.0) -> 9 | N10: =IFERROR(__xludf.DUMMYFUNCTION("""COMPUTED_VALUE"""),0.0) -> 0 | O10: =IFERROR(__xludf.DUMMYFUNCTION("""COMPUTED_VALUE"""),9.0) -> 9 | P10: =IFERROR(__xludf.DUMMYFUNCTION("""COMPUTED_VALUE"""),0.0) -> 0 | Q10: =IFERROR(__xludf.DUMMYFUNCTION("""COMPUTED_VALUE"""),"Yes") -> Yes | R10: =IFERROR(__xludf.DUMMYFUNCTION("""COMPUTED_VALUE"""),"No") -> No | S10: =IFERROR(__xludf.DUMMYFUNCTION("""COMPUTED_VALUE"""),"Yes") -> Yes | T10: =IFERROR(__xludf.DUMMYFUNCTION("""COMPUTED_VALUE"""),0.0) -> 0 | U10: =IFERROR(__xludf.DUMMYFUNCTION("""COMPUTED_VALUE"""),0.0) -> 0 | V10: =IFERROR(__xludf.DUMMYFUNCTION("""COMPUTED_VALUE"""),"اسلام میں عورت کا مقام کردار اور حق") -> اسلام میں عورت کا مقام کردار اور حق | W10: =IFERROR(__xludf.DUMMYFUNCTION("""COMPUTED_VALUE"""),"اسلام میں عورت کو بلند مقام دیا گیا ہے، جہاں وہ ماں، بیٹی، بہن اور بیوی کے طور پر عزت و احترام کی مستحق ہے۔ قرآن و حدیث کے مطابق، عورت کی تعلیم، حیا، اور عفت کو اہمیت دی گئی ہے، اور اسے معاشرتی ترقی میں فعال کردار ادا کرنے کی ترغیب دی گئی ہے۔") -> اسلام میں عورت کو بلند مقام دیا گیا ہے، جہاں وہ ماں، بیٹی، بہن اور بیوی کے طور پر عزت و احترام کی مستحق ہے۔ قرآن و حدیث کے مطابق، عورت کی تعلیم، حیا، اور عفت کو اہمیت دی گئی ہے، اور اسے معاشرتی ترقی میں فعال کردار ادا کرنے کی ترغیب دی گئی ہے۔ | X10: =IFERROR(__xludf.DUMMYFUNCTION("""COMPUTED_VALUE"""),0.0) -> 0 | Y10: =IFERROR(__xludf.DUMMYFUNCTION("""COMPUTED_VALUE"""),0.0) -> 0 | Z10: =IFERROR(__xludf.DUMMYFUNCTION("""COMPUTED_VALUE"""),2.0) -> 2 | AA10: =IFERROR(__xludf.DUMMYFUNCTION("""COMPUTED_VALUE"""),0.0) -> 0 | AB10: =IFERROR(__xludf.DUMMYFUNCTION("""COMPUTED_VALUE"""),0.0) -> 0 | AC10: =IFERROR(__xludf.DUMMYFUNCTION("""COMPUTED_VALUE"""),0.0) -> 0 | AD10: =IFERROR(__xludf.DUMMYFUNCTION("""COMPUTED_VALUE"""),0.0) -> 0 | AE10: =IFERROR(__xludf.DUMMYFUNCTION("""COMPUTED_VALUE"""),0.0) -> 0 | AF10: =IFERROR(__xludf.DUMMYFUNCTION("""COMPUTED_VALUE"""),7.0) -> 7 | AG10: =IFERROR(__xludf.DUMMYFUNCTION("""COMPUTED_VALUE"""),8.0) -> 8 | AH10: =IFERROR(__xludf.DUMMYFUNCTION("""COMPUTED_VALUE"""),0.0) -> 0 | AI10: =IFERROR(__xludf.DUMMYFUNCTION("""COMPUTED_VALUE"""),7.0) -> 7 | AJ10: =IFERROR(__xludf.DUMMYFUNCTION("""COMPUTED_VALUE"""),"https://drive.google.com/open?id=1oPWJKKn748a0HcKfgxjQY7OIPrQg83tC") -> https://drive.google.com/open?id=1oPWJKKn748a0HcKfgxjQY7OIPrQg83tC | AO10: 1 | AX10: 1
A11: 10 | B11: =IFERROR(__xludf.DUMMYFUNCTION("""COMPUTED_VALUE"""),45694.119361840276) -> 45694.119 | C11: =IFERROR(__xludf.DUMMYFUNCTION("""COMPUTED_VALUE"""),"Muhammad Ahsan") -> Muhammad Ahsan | D11: =IFERROR(__xludf.DUMMYFUNCTION("""COMPUTED_VALUE"""),"03078868667") -> 03078868667 | E11: =IFERROR(__xludf.DUMMYFUNCTION("""COMPUTED_VALUE"""),"شاہ ابوالمعالی") -> شاہ ابوالمعالی | F11: =IFERROR(__xludf.DUMMYFUNCTION("""COMPUTED_VALUE"""),"cqafr") -> cqafr | G11: =IFERROR(__xludf.DUMMYFUNCTION("""COMPUTED_VALUE"""),"Yes") -> Yes | H11: =IFERROR(__xludf.DUMMYFUNCTION("""COMPUTED_VALUE"""),0.0) -> 0 | I11: =IFERROR(__xludf.DUMMYFUNCTION("""COMPUTED_VALUE"""),10.0) -> 10 | J11: =IFERROR(__xludf.DUMMYFUNCTION("""COMPUTED_VALUE"""),0.0) -> 0 | K11: =IFERROR(__xludf.DUMMYFUNCTION("""COMPUTED_VALUE"""),1.0) -> 1 | L11: =IFERROR(__xludf.DUMMYFUNCTION("""COMPUTED_VALUE"""),0.0) -> 0 | M11: =IFERROR(__xludf.DUMMYFUNCTION("""COMPUTED_VALUE"""),0.0) -> 0 | N11: =IFERROR(__xludf.DUMMYFUNCTION("""COMPUTED_VALUE"""),0.0) -> 0 | O11: =IFERROR(__xludf.DUMMYFUNCTION("""COMPUTED_VALUE"""),0.0) -> 0 | P11: =IFERROR(__xludf.DUMMYFUNCTION("""COMPUTED_VALUE"""),0.0) -> 0 | Q11: =IFERROR(__xludf.DUMMYFUNCTION("""COMPUTED_VALUE"""),"No") -> No | R11: =IFERROR(__xludf.DUMMYFUNCTION("""COMPUTED_VALUE"""),"No") -> No | S11: =IFERROR(__xludf.DUMMYFUNCTION("""COMPUTED_VALUE"""),"No") -> No | T11: =IFERROR(__xludf.DUMMYFUNCTION("""COMPUTED_VALUE"""),0.0) -> 0 | U11: =IFERROR(__xludf.DUMMYFUNCTION("""COMPUTED_VALUE"""),0.0) -> 0 | V11: =IFERROR(__xludf.DUMMYFUNCTION("""COMPUTED_VALUE"""),"Issue of Kashmir") -> Issue of Kashmir | W11: =IFERROR(__xludf.DUMMYFUNCTION("""COMPUTED_VALUE"""),"imam na apna bayan ma kashmir or is par hona walal zulam par bat ke") -> imam na apna bayan ma kashmir or is par hona walal zulam par bat ke | X11: =IFERROR(__xludf.DUMMYFUNCTION("""COMPUTED_VALUE"""),0.0) -> 0 | Y11: =IFERROR(__xludf.DUMMYFUNCTION("""COMPUTED_VALUE"""),1.0) -> 1 | Z11: =IFERROR(__xludf.DUMMYFUNCTION("""COMPUTED_VALUE"""),1.0) -> 1 | AA11: =IFERROR(__xludf.DUMMYFUNCTION("""COMPUTED_VALUE"""),2.0) -> 2 | AB11: =IFERROR(__xludf.DUMMYFUNCTION("""COMPUTED_VALUE"""),2.0) -> 2 | AC11: =IFERROR(__xludf.DUMMYFUNCTION("""COMPUTED_VALUE"""),5.0) -> 5 | AD11: =IFERROR(__xludf.DUMMYFUNCTION("""COMPUTED_VALUE"""),0.0) -> 0 | AE11: =IFERROR(__xludf.DUMMYFUNCTION("""COMPUTED_VALUE"""),0.0) -> 0 | AF11: =IFERROR(__xludf.DUMMYFUNCTION("""COMPUTED_VALUE"""),0.0) -> 0 | AG11: =IFERROR(__xludf.DUMMYFUNCTION("""COMPUTED_VALUE"""),9.0) -> 9 | AH11: =IFERROR(__xludf.DUMMYFUNCTION("""COMPUTED_VALUE"""),0.0) -> 0 | AI11: =IFERROR(__xludf.DUMMYFUNCTION("""COMPUTED_VALUE"""),8.0) -> 8 | AJ11: =IFERROR(__xludf.DUMMYFUNCTION("""COMPUTED_VALUE"""),"https://drive.google.com/open?id=1jM17BBHEVehMhVigSU1jIjio2ohBwFzz") -> https://drive.google.com/open?id=1jM17BBHEVehMhVigSU1jIjio2ohBwFzz | AO11: 1 | AX11: 1
A12: 11 | B12: =IFERROR(__xludf.DUMMYFUNCTION("""COMPUTED_VALUE"""),45695.09888276621) -> 45695.099 | C12: =IFERROR(__xludf.DUMMYFUNCTION("""COMPUTED_VALUE"""),"Hafiz Ali Usman ") -> Hafiz Ali Usman | D12: =IFERROR(__xludf.DUMMYFUNCTION("""COMPUTED_VALUE"""),"03035218874") -> 03035218874 | E12: =IFERROR(__xludf.DUMMYFUNCTION("""COMPUTED_VALUE""")," جامع مسجد مسافر خانہ گڑ ھی شاھولاہور Jamia Masjid Musafir Khana Ghari Shah Lahore") -> جامع مسجد مسافر خانہ گڑ ھی شاھولاہور Jamia Masjid Musafir Khana Ghari Shah Lahore | F12: =IFERROR(__xludf.DUMMYFUNCTION("""COMPUTED_VALUE"""),"emotn") -> emotn | G12: =IFERROR(__xludf.DUMMYFUNCTION("""COMPUTED_VALUE"""),"Yes") -> Yes | H12: =IFERROR(__xludf.DUMMYFUNCTION("""COMPUTED_VALUE"""),5.0) -> 5 | I12: =IFERROR(__xludf.DUMMYFUNCTION("""COMPUTED_VALUE"""),8.0) -> 8 | J12: =IFERROR(__xludf.DUMMYFUNCTION("""COMPUTED_VALUE"""),3.0) -> 3 | K12: =IFERROR(__xludf.DUMMYFUNCTION("""COMPUTED_VALUE"""),6.0) -> 6 | L12: =IFERROR(__xludf.DUMMYFUNCTION("""COMPUTED_VALUE"""),0.0) -> 0 | M12: =IFERROR(__xludf.DUMMYFUNCTION("""COMPUTED_VALUE"""),4.0) -> 4 | N12: =IFERROR(__xludf.DUMMYFUNCTION("""COMPUTED_VALUE"""),1.0) -> 1 | O12: =IFERROR(__xludf.DUMMYFUNCTION("""COMPUTED_VALUE"""),7.0) -> 7 | P12: =IFERROR(__xludf.DUMMYFUNCTION("""COMPUTED_VALUE"""),4.0) -> 4 | Q12: =IFERROR(__xludf.DUMMYFUNCTION("""COMPUTED_VALUE"""),"No") -> No | R12: =IFERROR(__xludf.DUMMYFUNCTION("""COMPUTED_VALUE"""),"No") -> No | S12: =IFERROR(__xludf.DUMMYFUNCTION("""COMPUTED_VALUE"""),"No") -> No | T12: =IFERROR(__xludf.DUMMYFUNCTION("""COMPUTED_VALUE"""),5.0) -> 5 | U12: =IFERROR(__xludf.DUMMYFUNCTION("""COMPUTED_VALUE"""),0.0) -> 0 | V12: =IFERROR(__xludf.DUMMYFUNCTION("""COMPUTED_VALUE"""),"Aurt k haqooq ki bat ki") -> Aurt k haqooq ki bat ki | W12: =IFERROR(__xludf.DUMMYFUNCTION("""COMPUTED_VALUE"""),"Aurt ki parwarish per bat ki ") -> Aurt ki parwarish per bat ki | X12: =IFERROR(__xludf.DUMMYFUNCTION("""COMPUTED_VALUE"""),2.0) -> 2 | Y12: =IFERROR(__xludf.DUMMYFUNCTION("""COMPUTED_VALUE"""),3.0) -> 3 | Z12: =IFERROR(__xludf.DUMMYFUNCTION("""COMPUTED_VALUE"""),6.0) -> 6 | AA12: =IFERROR(__xludf.DUMMYFUNCTION("""COMPUTED_VALUE"""),5.0) -> 5 | AB12: =IFERROR(__xludf.DUMMYFUNCTION("""COMPUTED_VALUE"""),2.0) -> 2 | AC12: =IFERROR(__xludf.DUMMYFUNCTION("""COMPUTED_VALUE"""),0.0) -> 0 | AD12: =IFERROR(__xludf.DUMMYFUNCTION("""COMPUTED_VALUE"""),0.0) -> 0 | AE12: =IFERROR(__xludf.DUMMYFUNCTION("""COMPUTED_VALUE"""),0.0) -> 0 | AF12: =IFERROR(__xludf.DUMMYFUNCTION("""COMPUTED_VALUE"""),6.0) -> 6 | AG12: =IFERROR(__xludf.DUMMYFUNCTION("""COMPUTED_VALUE"""),6.0) -> 6 | AH12: =IFERROR(__xludf.DUMMYFUNCTION("""COMPUTED_VALUE"""),3.0) -> 3 | AI12: =IFERROR(__xludf.DUMMYFUNCTION("""COMPUTED_VALUE"""),5.0) -> 5 | AJ12: =IFERROR(__xludf.DUMMYFUNCTION("""COMPUTED_VALUE"""),"https://drive.google.com/open?id=1ONPn__gcw6Ai491mKT8sb3SSFxWFNQWr") -> https://drive.google.com/open?id=1ONPn__gcw6Ai491mKT8sb3SSFxWFNQWr | AO12: 1 | AX12: 1
A13: 12 | B13: =IFERROR(__xludf.DUMMYFUNCTION("""COMPUTED_VALUE"""),45695.99316229166) -> 45695.993 | C13: =IFERROR(__xludf.DUMMYFUNCTION("""COMPUTED_VALUE"""),"Adnan Ali ") -> Adnan Ali | D13: =IFERROR(__xludf.DUMMYFUNCTION("""COMPUTED_VALUE"""),"03054045395") -> 03054045395 | E13: =IFERROR(__xludf.DUMMYFUNCTION("""COMPUTED_VALUE"""),"Jamia Masjid Barkat bibi ") -> Jamia Masjid Barkat bibi | F13: =IFERROR(__xludf.DUMMYFUNCTION("""COMPUTED_VALUE"""),"HSWIF") -> HSWIF | G13: =IFERROR(__xludf.DUMMYFUNCTION("""COMPUTED_VALUE"""),"Yes") -> Yes | H13: =IFERROR(__xludf.DUMMYFUNCTION("""COMPUTED_VALUE"""),7.0) -> 7 | I13: =IFERROR(__xludf.DUMMYFUNCTION("""COMPUTED_VALUE"""),3.0) -> 3 | J13: =IFERROR(__xludf.DUMMYFUNCTION("""COMPUTED_VALUE"""),7.0) -> 7 | K13: =IFERROR(__xludf.DUMMYFUNCTION("""COMPUTED_VALUE"""),7.0) -> 7 | L13: =IFERROR(__xludf.DUMMYFUNCTION("""COMPUTED_VALUE"""),0.0) -> 0 | M13: =IFERROR(__xludf.DUMMYFUNCTION("""COMPUTED_VALUE"""),6.0) -> 6 | N13: =IFERROR(__xludf.DUMMYFUNCTION("""COMPUTED_VALUE"""),0.0) -> 0 | O13: =IFERROR(__xludf.DUMMYFUNCTION("""COMPUTED_VALUE"""),8.0) -> 8 | P13: =IFERROR(__xludf.DUMMYFUNCTION("""COMPUTED_VALUE"""),0.0) -> 0 | Q13: =IFERROR(__xludf.DUMMYFUNCTION("""COMPUTED_VALUE"""),"Yes") -> Yes | R13: =IFERROR(__xludf.DUMMYFUNCTION("""COMPUTED_VALUE"""),"No") -> No | S13: =IFERROR(__xludf.DUMMYFUNCTION("""COMPUTED_VALUE"""),"Yes") -> Yes | T13: =IFERROR(__xludf.DUMMYFUNCTION("""COMPUTED_VALUE"""),0.0) -> 0 | U13: =IFERROR(__xludf.DUMMYFUNCTION("""COMPUTED_VALUE"""),0.0) -> 0 | V13: =IFERROR(__xludf.DUMMYFUNCTION("""COMPUTED_VALUE"""),"اسلام میں عورت کا مقام کردار اور حق") -> اسلام میں عورت کا مقام کردار اور حق | W13: =IFERROR(__xludf.DUMMYFUNCTION("""COMPUTED_VALUE"""),"اسلام میں عورت کو عزت اور حقوق دیے گئے ہیں، جیسے تعلیم، وراثت اور معاشرتی تحفظ۔ اسلام عورت کو مرد کے برابر حقوق دیتا ہے اور اس کی عزت و وقار کی حفاظت کرتا ہے۔") -> اسلام میں عورت کو عزت اور حقوق دیے گئے ہیں، جیسے تعلیم، وراثت اور معاشرتی تحفظ۔ اسلام عورت کو مرد کے برابر حقوق دیتا ہے اور اس کی عزت و وقار کی حفاظت کرتا ہے۔ | X13: =IFERROR(__xludf.DUMMYFUNCTION("""COMPUTED_VALUE"""),0.0) -> 0 | Y13: =IFERROR(__xludf.DUMMYFUNCTION("""COMPUTED_VALUE"""),0.0) -> 0 | Z13: =IFERROR(__xludf.DUMMYFUNCTION("""COMPUTED_VALUE"""),0.0) -> 0 | AA13: =IFERROR(__xludf.DUMMYFUNCTION("""COMPUTED_VALUE"""),0.0) -> 0 | AB13: =IFERROR(__xludf.DUMMYFUNCTION("""COMPUTED_VALUE"""),0.0) -> 0 | AC13: =IFERROR(__xludf.DUMMYFUNCTION("""COMPUTED_VALUE"""),0.0) -> 0 | AD13: =IFERROR(__xludf.DUMMYFUNCTION("""COMPUTED_VALUE"""),0.0) -> 0 | AE13: =IFERROR(__xludf.DUMMYFUNCTION("""COMPUTED_VALUE"""),0.0) -> 0 | AF13: =IFERROR(__xludf.DUMMYFUNCTION("""COMPUTED_VALUE"""),8.0) -> 8 | AG13: =IFERROR(__xludf.DUMMYFUNCTION("""COMPUTED_VALUE"""),8.0) -> 8 | AH13: =IFERROR(__xludf.DUMMYFUNCTION("""COMPUTED_VALUE"""),0.0) -> 0 | AI13: =IFERROR(__xludf.DUMMYFUNCTION("""COMPUTED_VALUE"""),8.0) -> 8 | AJ13: =IFERROR(__xludf.DUMMYFUNCTION("""COMPUTED_VALUE"""),"https://drive.google.com/open?id=132T7Gtw7hWXGyB3cpT9M5p4rVFtCvsb-") -> https://drive.google.com/open?id=132T7Gtw7hWXGyB3cpT9M5p4rVFtCvsb- | AO13: 1 | AX13: 1
A14: 13 | B14: =IFERROR(__xludf.DUMMYFUNCTION("""COMPUTED_VALUE"""),45697.08860956019) -> 45697.089 | C14: =IFERROR(__xludf.DUMMYFUNCTION("""COMPUTED_VALUE"""),"Shakeela Rafique") -> Shakeela Rafique | D14: =IFERROR(__xludf.DUMMYFUNCTION("""COMPUTED_VALUE"""),"03359485820") -> 03359485820 | E14: =IFERROR(__xludf.DUMMYFUNCTION("""COMPUTED_VALUE"""),"Jamia Masjid takiya kabooter shah") -> Jamia Masjid takiya kabooter shah | F14: =IFERROR(__xludf.DUMMYFUNCTION("""COMPUTED_VALUE"""),"umifn") -> umifn | G14: =IFERROR(__xludf.DUMMYFUNCTION("""COMPUTED_VALUE"""),"No") -> No | K14: =IFERROR(__xludf.DUMMYFUNCTION("""COMPUTED_VALUE"""),0.0) -> 0 | L14: =IFERROR(__xludf.DUMMYFUNCTION("""COMPUTED_VALUE"""),0.0) -> 0 | M14: =IFERROR(__xludf.DUMMYFUNCTION("""COMPUTED_VALUE"""),0.0) -> 0 | N14: =IFERROR(__xludf.DUMMYFUNCTION("""COMPUTED_VALUE"""),0.0) -> 0 | O14: =IFERROR(__xludf.DUMMYFUNCTION("""COMPUTED_VALUE"""),0.0) -> 0 | P14: =IFERROR(__xludf.DUMMYFUNCTION("""COMPUTED_VALUE"""),0.0) -> 0 | Q14: =IFERROR(__xludf.DUMMYFUNCTION("""COMPUTED_VALUE"""),"No") -> No | R14: =IFERROR(__xludf.DUMMYFUNCTION("""COMPUTED_VALUE"""),"No") -> No | S14: =IFERROR(__xludf.DUMMYFUNCTION("""COMPUTED_VALUE"""),"No") -> No | T14: =IFERROR(__xludf.DUMMYFUNCTION("""COMPUTED_VALUE"""),0.0) -> 0 | U14: =IFERROR(__xludf.DUMMYFUNCTION("""COMPUTED_VALUE"""),0.0) -> 0 | V14: =IFERROR(__xludf.DUMMYFUNCTION("""COMPUTED_VALUE"""),"meeraj sharif") -> meeraj sharif | W14: =IFERROR(__xludf.DUMMYFUNCTION("""COMPUTED_VALUE"""),"waqia meeraj aur seerat un nabi saw byan kiya") -> waqia meeraj aur seerat un nabi saw byan kiya | X14: =IFERROR(__xludf.DUMMYFUNCTION("""COMPUTED_VALUE"""),7.0) -> 7 | Y14: =IFERROR(__xludf.DUMMYFUNCTION("""COMPUTED_VALUE"""),5.0) -> 5 | Z14: =IFERROR(__xludf.DUMMYFUNCTION("""COMPUTED_VALUE"""),1.0) -> 1 | AA14: =IFERROR(__xludf.DUMMYFUNCTION("""COMPUTED_VALUE"""),8.0) -> 8 | AB14: =IFERROR(__xludf.DUMMYFUNCTION("""COMPUTED_VALUE"""),8.0) -> 8 | AC14: =IFERROR(__xludf.DUMMYFUNCTION("""COMPUTED_VALUE"""),6.0) -> 6 | AD14: =IFERROR(__xludf.DUMMYFUNCTION("""COMPUTED_VALUE"""),4.0) -> 4 | AE14: =IFERROR(__xludf.DUMMYFUNCTION("""COMPUTED_VALUE"""),0.0) -> 0 | AF14: =IFERROR(__xludf.DUMMYFUNCTION("""COMPUTED_VALUE"""),6.0) -> 6 | AG14: =IFERROR(__xludf.DUMMYFUNCTION("""COMPUTED_VALUE"""),6.0) -> 6 | AH14: =IFERROR(__xludf.DUMMYFUNCTION("""COMPUTED_VALUE"""),0.0) -> 0 | AI14: =IFERROR(__xludf.DUMMYFUNCTION("""COMPUTED_VALUE"""),6.0) -> 6 | AJ14: =IFERROR(__xludf.DUMMYFUNCTION("""COMPUTED_VALUE"""),"https://drive.google.com/open?id=1A8rWyxlVLIcNcIvRBjhA4QbhbExHkgWX") -> https://drive.google.com/open?id=1A8rWyxlVLIcNcIvRBjhA4QbhbExHkgWX | AK14: =IFERROR(__xludf.DUMMYFUNCTION("""COMPUTED_VALUE"""),"no") -> no | AO14: 1 | AX14: 1
A15: 14 | B15: =IFERROR(__xludf.DUMMYFUNCTION("""COMPUTED_VALUE"""),45698.02454076389) -> 45698.025 | C15: =IFERROR(__xludf.DUMMYFUNCTION("""COMPUTED_VALUE"""),"Shakeela Rafique") -> Shakeela Rafique | D15: =IFERROR(__xludf.DUMMYFUNCTION("""COMPUTED_VALUE"""),"03359485820") -> 03359485820 | E15: =IFERROR(__xludf.DUMMYFUNCTION("""COMPUTED_VALUE"""),"jamia Masjid Texali gate") -> jamia Masjid Texali gate | F15: =IFERROR(__xludf.DUMMYFUNCTION("""COMPUTED_VALUE"""),"fitmr") -> fitmr | G15: =IFERROR(__xludf.DUMMYFUNCTION("""COMPUTED_VALUE"""),"No") -> No | K15: =IFERROR(__xludf.DUMMYFUNCTION("""COMPUTED_VALUE"""),7.0) -> 7 | L15: =IFERROR(__xludf.DUMMYFUNCTION("""COMPUTED_VALUE"""),8.0) -> 8 | M15: =IFERROR(__xludf.DUMMYFUNCTION("""COMPUTED_VALUE"""),0.0) -> 0 | N15: =IFERROR(__xludf.DUMMYFUNCTION("""COMPUTED_VALUE"""),9.0) -> 9 | O15: =IFERROR(__xludf.DUMMYFUNCTION("""COMPUTED_VALUE"""),0.0) -> 0 | P15: =IFERROR(__xludf.DUMMYFUNCTION("""COMPUTED_VALUE"""),8.0) -> 8 | Q15: =IFERROR(__xludf.DUMMYFUNCTION("""COMPUTED_VALUE"""),"No") -> No | R15: =IFERROR(__xludf.DUMMYFUNCTION("""COMPUTED_VALUE"""),"Yes") -> Yes | S15: =IFERROR(__xludf.DUMMYFUNCTION("""COMPUTED_VALUE"""),"No") -> No | T15: =IFERROR(__xludf.DUMMYFUNCTION("""COMPUTED_VALUE"""),0.0) -> 0 | U15: =IFERROR(__xludf.DUMMYFUNCTION("""COMPUTED_VALUE"""),9.0) -> 9 | V15: =IFERROR(__xludf.DUMMYFUNCTION("""COMPUTED_VALUE"""),"Parasion K haqooq") -> Parasion K haqooq | W15: =IFERROR(__xludf.DUMMYFUNCTION("""COMPUTED_VALUE"""),"parasion k haqqoq") -> parasion k haqqoq | X15: =IFERROR(__xludf.DUMMYFUNCTION("""COMPUTED_VALUE"""),3.0) -> 3 | Y15: =IFERROR(__xludf.DUMMYFUNCTION("""COMPUTED_VALUE"""),8.0) -> 8 | Z15: =IFERROR(__xludf.DUMMYFUNCTION("""COMPUTED_VALUE"""),2.0) -> 2 | AA15: =IFERROR(__xludf.DUMMYFUNCTION("""COMPUTED_VALUE"""),3.0) -> 3 | AB15: =IFERROR(__xludf.DUMMYFUNCTION("""COMPUTED_VALUE"""),0.0) -> 0 | AC15: =IFERROR(__xludf.DUMMYFUNCTION("""COMPUTED_VALUE"""),0.0) -> 0 | AD15: =IFERROR(__xludf.DUMMYFUNCTION("""COMPUTED_VALUE"""),0.0) -> 0 | AE15: =IFERROR(__xludf.DUMMYFUNCTION("""COMPUTED_VALUE"""),0.0) -> 0 | AF15: =IFERROR(__xludf.DUMMYFUNCTION("""COMPUTED_VALUE"""),0.0) -> 0 | AG15: =IFERROR(__xludf.DUMMYFUNCTION("""COMPUTED_VALUE"""),6.0) -> 6 | AH15: =IFERROR(__xludf.DUMMYFUNCTION("""COMPUTED_VALUE"""),0.0) -> 0 | AI15: =IFERROR(__xludf.DUMMYFUNCTION("""COMPUTED_VALUE"""),6.0) -> 6 | AJ15: =IFERROR(__xludf.DUMMYFUNCTION("""COMPUTED_VALUE"""),"https://drive.google.com/open?id=1cSO6tLLNGXdiQN0KKxsqjeKW8iS__Li5") -> https://drive.google.com/open?id=1cSO6tLLNGXdiQN0KKxsqjeKW8iS__Li5 | AK15: =IFERROR(__xludf.DUMMYFUNCTION("""COMPUTED_VALUE"""),"no") -> no | AO15: 1 | AX15: 1
A16: 15 | B16: =IFERROR(__xludf.DUMMYFUNCTION("""COMPUTED_VALUE"""),45699.031141747684) -> 45699.031 | C16: =IFERROR(__xludf.DUMMYFUNCTION("""COMPUTED_VALUE"""),"Bilal") -> Bilal | D16: =IFERROR(__xludf.DUMMYFUNCTION("""COMPUTED_VALUE"""),"03066761947") -> 03066761947 | E16: =IFERROR(__xludf.DUMMYFUNCTION("""COMPUTED_VALUE"""),"Jaima masjid bohaar wali lohare gate lahore") -> Jaima masjid bohaar wali lohare gate lahore | F16: =IFERROR(__xludf.DUMMYFUNCTION("""COMPUTED_VALUE"""),"oonhe") -> oonhe | G16: =IFERROR(__xludf.DUMMYFUNCTION("""COMPUTED_VALUE"""),"Yes") -> Yes | H16: =IFERROR(__xludf.DUMMYFUNCTION("""COMPUTED_VALUE"""),9.0) -> 9 | I16: =IFERROR(__xludf.DUMMYFUNCTION("""COMPUTED_VALUE"""),5.0) -> 5 | J16: =IFERROR(__xludf.DUMMYFUNCTION("""COMPUTED_VALUE"""),7.0) -> 7 | K16: =IFERROR(__xludf.DUMMYFUNCTION("""COMPUTED_VALUE"""),10.0) -> 10 | L16: =IFERROR(__xludf.DUMMYFUNCTION("""COMPUTED_VALUE"""),10.0) -> 10 | M16: =IFERROR(__xludf.DUMMYFUNCTION("""COMPUTED_VALUE"""),10.0) -> 10 | N16: =IFERROR(__xludf.DUMMYFUNCTION("""COMPUTED_VALUE"""),10.0) -> 10 | O16: =IFERROR(__xludf.DUMMYFUNCTION("""COMPUTED_VALUE"""),5.0) -> 5 | P16: =IFERROR(__xludf.DUMMYFUNCTION("""COMPUTED_VALUE"""),10.0) -> 10 | Q16: =IFERROR(__xludf.DUMMYFUNCTION("""COMPUTED_VALUE"""),"No") -> No | R16: =IFERROR(__xludf.DUMMYFUNCTION("""COMPUTED_VALUE"""),"Yes") -> Yes | S16: =IFERROR(__xludf.DUMMYFUNCTION("""COMPUTED_VALUE"""),"No") -> No | T16: =IFERROR(__xludf.DUMMYFUNCTION("""COMPUTED_VALUE"""),0.0) -> 0 | U16: =IFERROR(__xludf.DUMMYFUNCTION("""COMPUTED_VALUE"""),0.0) -> 0 | V16: =IFERROR(__xludf.DUMMYFUNCTION("""COMPUTED_VALUE"""),"Parasuon k hakooq") -> Parasuon k hakooq | W16: =IFERROR(__xludf.DUMMYFUNCTION("""COMPUTED_VALUE"""),"Paraseuo k hakooq") -> Paraseuo k hakooq | X16: =IFERROR(__xludf.DUMMYFUNCTION("""COMPUTED_VALUE"""),8.0) -> 8 | Y16: =IFERROR(__xludf.DUMMYFUNCTION("""COMPUTED_VALUE"""),10.0) -> 10 | Z16: =IFERROR(__xludf.DUMMYFUNCTION("""COMPUTED_VALUE"""),8.0) -> 8 | AA16: =IFERROR(__xludf.DUMMYFUNCTION("""COMPUTED_VALUE"""),9.0) -> 9 | AB16: =IFERROR(__xludf.DUMMYFUNCTION("""COMPUTED_VALUE"""),9.0) -> 9 | AC16: =IFERROR(__xludf.DUMMYFUNCTION("""COMPUTED_VALUE"""),10.0) -> 10 | AD16: =IFERROR(__xludf.DUMMYFUNCTION("""COMPUTED_VALUE"""),2.0) -> 2 | AE16: =IFERROR(__xludf.DUMMYFUNCTION("""COMPUTED_VALUE"""),1.0) -> 1 | AF16: =IFERROR(__xludf.DUMMYFUNCTION("""COMPUTED_VALUE"""),10.0) -> 10 | AG16: =IFERROR(__xludf.DUMMYFUNCTION("""COMPUTED_VALUE"""),10.0) -> 10 | AH16: =IFERROR(__xludf.DUMMYFUNCTION("""COMPUTED_VALUE"""),0.0) -> 0 | AI16: =IFERROR(__xludf.DUMMYFUNCTION("""COMPUTED_VALUE"""),10.0) -> 10 | AJ16: =IFERROR(__xludf.DUMMYFUNCTION("""COMPUTED_VALUE"""),"https://drive.google.com/open?id=1-B-LE23gtDIabp76cwDES8uVNbWHEd2r") -> https://drive.google.com/open?id=1-B-LE23gtDIabp76cwDES8uVNbWHEd2r | AO16: 2 | AX16: 2
A17: 16 | B17: =IFERROR(__xludf.DUMMYFUNCTION("""COMPUTED_VALUE"""),45699.16125875) -> 45699.161 | C17: =IFERROR(__xludf.DUMMYFUNCTION("""COMPUTED_VALUE"""),"Usman Tariq ") -> Usman Tariq | D17: =IFERROR(__xludf.DUMMYFUNCTION("""COMPUTED_VALUE"""),"03081862531") -> 03081862531 | E17: =IFERROR(__xludf.DUMMYFUNCTION("""COMPUTED_VALUE"""),"Jamiea masjid taxali gate Lahore ") -> Jamiea masjid taxali gate Lahore | F17: =IFERROR(__xludf.DUMMYFUNCTION("""COMPUTED_VALUE"""),"FITMR") -> FITMR | G17: =IFERROR(__xludf.DUMMYFUNCTION("""COMPUTED_VALUE"""),"Yes") -> Yes | H17: =IFERROR(__xludf.DUMMYFUNCTION("""COMPUTED_VALUE"""),10.0) -> 10 | I17: =IFERROR(__xludf.DUMMYFUNCTION("""COMPUTED_VALUE"""),3.0) -> 3 | J17: =IFERROR(__xludf.DUMMYFUNCTION("""COMPUTED_VALUE"""),10.0) -> 10 | K17: =IFERROR(__xludf.DUMMYFUNCTION("""COMPUTED_VALUE"""),10.0) -> 10 | L17: =IFERROR(__xludf.DUMMYFUNCTION("""COMPUTED_VALUE"""),10.0) -> 10 | M17: =IFERROR(__xludf.DUMMYFUNCTION("""COMPUTED_VALUE"""),3.0) -> 3 | N17: =IFERROR(__xludf.DUMMYFUNCTION("""COMPUTED_VALUE"""),10.0) -> 10 | O17: =IFERROR(__xludf.DUMMYFUNCTION("""COMPUTED_VALUE"""),0.0) -> 0 | P17: =IFERROR(__xludf.DUMMYFUNCTION("""COMPUTED_VALUE"""),10.0) -> 10 | Q17: =IFERROR(__xludf.DUMMYFUNCTION("""COMPUTED_VALUE"""),"No") -> No | R17: =IFERROR(__xludf.DUMMYFUNCTION("""COMPUTED_VALUE"""),"Yes") -> Yes | S17: =IFERROR(__xludf.DUMMYFUNCTION("""COMPUTED_VALUE"""),"No") -> No | T17: =IFERROR(__xludf.DUMMYFUNCTION("""COMPUTED_VALUE"""),0.0) -> 0 | U17: =IFERROR(__xludf.DUMMYFUNCTION("""COMPUTED_VALUE"""),10.0) -> 10 | V17: =IFERROR(__xludf.DUMMYFUNCTION("""COMPUTED_VALUE"""),"Hamsieo h haqouq haqouq ul abaad") -> Hamsieo h haqouq haqouq ul abaad | W17: =IFERROR(__xludf.DUMMYFUNCTION("""COMPUTED_VALUE"""),"Bnday ka haq bnady per hai Jis ka sawal ho ga haqouq ul abaad ka lazmi poucha jaiy ga") -> Bnday ka haq bnady per hai Jis ka sawal ho ga haqouq ul abaad ka lazmi poucha jaiy ga | X17: =IFERROR(__xludf.DUMMYFUNCTION("""COMPUTED_VALUE"""),1.0) -> 1 | Y17: =IFERROR(__xludf.DUMMYFUNCTION("""COMPUTED_VALUE"""),10.0) -> 10 | Z17: =IFERROR(__xludf.DUMMYFUNCTION("""COMPUTED_VALUE"""),8.0) -> 8 | AA17: =IFERROR(__xludf.DUMMYFUNCTION("""COMPUTED_VALUE"""),4.0) -> 4 | AB17: =IFERROR(__xludf.DUMMYFUNCTION("""COMPUTED_VALUE"""),2.0) -> 2 | AC17: =IFERROR(__xludf.DUMMYFUNCTION("""COMPUTED_VALUE"""),1.0) -> 1 | AD17: =IFERROR(__xludf.DUMMYFUNCTION("""COMPUTED_VALUE"""),1.0) -> 1 | AE17: =IFERROR(__xludf.DUMMYFUNCTION("""COMPUTED_VALUE"""),0.0) -> 0 | AF17: =IFERROR(__xludf.DUMMYFUNCTION("""COMPUTED_VALUE"""),9.0) -> 9 | AG17: =IFERROR(__xludf.DUMMYFUNCTION("""COMPUTED_VALUE"""),10.0) -> 10 | AH17: =IFERROR(__xludf.DUMMYFUNCTION("""COMPUTED_VALUE"""),0.0) -> 0 | AI17: =IFERROR(__xludf.DUMMYFUNCTION("""COMPUTED_VALUE"""),10.0) -> 10 | AJ17: =IFERROR(__xludf.DUMMYFUNCTION("""COMPUTED_VALUE"""),"https://drive.google.com/open?id=1JwMLp1VMOGzuqaxmZQpSyNvLfIS9GrDr") -> https://drive.google.com/open?id=1JwMLp1VMOGzuqaxmZQpSyNvLfIS9GrDr | AO17: 2 | AX17: 2
